(venv) ~/workspace/backend-codes-gd$ python manage.py makemigrations
Traceback (most recent call last):
  File "/home/runner/workspace/.pythonlibs/lib/python3.12/site-packages/environ/environ.py", line 388, in get_value
    value = self.ENVIRON[var_name]
            ~~~~~~~~~~~~^^^^^^^^^^
  File "<frozen os>", line 714, in __getitem__
KeyError: 'EMAIL_HOST'

The above exception was the direct cause of the following exception:

Traceback (most recent call last):
  File "/home/runner/workspace/backend-codes-gd/manage.py", line 22, in <module>
    main()
  File "/home/runner/workspace/backend-codes-gd/manage.py", line 18, in main
    execute_from_command_line(sys.argv)
  File "/home/runner/workspace/.pythonlibs/lib/python3.12/site-packages/django/core/management/__init__.py", line 442, in execute_from_command_line
    utility.execute()
  File "/home/runner/workspace/.pythonlibs/lib/python3.12/site-packages/django/core/management/__init__.py", line 436, in execute
    self.fetch_command(subcommand).run_from_argv(self.argv)
  File "/home/runner/workspace/.pythonlibs/lib/python3.12/site-packages/django/core/management/base.py", line 412, in run_from_argv
    self.execute(*args, **cmd_options)
  File "/home/runner/workspace/.pythonlibs/lib/python3.12/site-packages/django/core/management/base.py", line 453, in execute
    self.check()
  File "/home/runner/workspace/.pythonlibs/lib/python3.12/site-packages/django/core/management/base.py", line 485, in check
    all_issues = checks.run_checks(
                 ^^^^^^^^^^^^^^^^^^
  File "/home/runner/workspace/.pythonlibs/lib/python3.12/site-packages/django/core/checks/registry.py", line 88, in run_checks
    new_errors = check(app_configs=app_configs, databases=databases)
                 ^^^^^^^^^^^^^^^^^^^^^^^^^^^^^^^^^^^^^^^^^^^^^^^^^^^
  File "/home/runner/workspace/.pythonlibs/lib/python3.12/site-packages/django/core/checks/urls.py", line 10, in check_url_config
    if getattr(settings, "ROOT_URLCONF", None):
       ^^^^^^^^^^^^^^^^^^^^^^^^^^^^^^^^^^^^^^^
  File "/home/runner/workspace/.pythonlibs/lib/python3.12/site-packages/django/conf/__init__.py", line 102, in __getattr__
    self._setup(name)
  File "/home/runner/workspace/.pythonlibs/lib/python3.12/site-packages/django/conf/__init__.py", line 89, in _setup
    self._wrapped = Settings(settings_module)
                    ^^^^^^^^^^^^^^^^^^^^^^^^^
  File "/home/runner/workspace/.pythonlibs/lib/python3.12/site-packages/django/conf/__init__.py", line 217, in __init__
    mod = importlib.import_module(self.SETTINGS_MODULE)
          ^^^^^^^^^^^^^^^^^^^^^^^^^^^^^^^^^^^^^^^^^^^^^
  File "/nix/store/vnvdzw4182wb2ifzi0cczhv80yfnpx1q-python3-3.12.11/lib/python3.12/importlib/__init__.py", line 90, in import_module
    return _bootstrap._gcd_import(name[level:], package, level)
           ^^^^^^^^^^^^^^^^^^^^^^^^^^^^^^^^^^^^^^^^^^^^^^^^^^^^
  File "<frozen importlib._bootstrap>", line 1387, in _gcd_import
  File "<frozen importlib._bootstrap>", line 1360, in _find_and_load
  File "<frozen importlib._bootstrap>", line 1331, in _find_and_load_unlocked
  File "<frozen importlib._bootstrap>", line 935, in _load_unlocked
  File "<frozen importlib._bootstrap_external>", line 999, in exec_module
  File "<frozen importlib._bootstrap>", line 488, in _call_with_frames_removed
  File "/home/runner/workspace/backend-codes-gd/settings/development.py", line 1, in <module>
    from .base import *
  File "/home/runner/workspace/backend-codes-gd/settings/base.py", line 218, in <module>
    EMAIL_HOST = env('EMAIL_HOST')
                 ^^^^^^^^^^^^^^^^^
  File "/home/runner/workspace/.pythonlibs/lib/python3.12/site-packages/environ/environ.py", line 199, in __call__
    return self.get_value(
           ^^^^^^^^^^^^^^^
  File "/home/runner/workspace/.pythonlibs/lib/python3.12/site-packages/environ/environ.py", line 392, in get_value
    raise ImproperlyConfigured(error_msg) from exc
django.core.exceptions.ImproperlyConfigured: Set the EMAIL_HOST environment variable